Workbook

Sheet Instructions
A1: AHP Calculator — Instructions
A3: 1. Print or send the companion file AHP_Expert_Survey.docx to your marketing expert(s).
A4: 2. Once the expert returns the completed survey, open this workbook.
A5: 3. Go to the 'Criteria Weights' sheet and enter the expert's ratings in the YELLOW input cells, following the same +1 to +9 / -1 to -9 convention used in the survey (positive = left item preferred, negative = right item preferred).
A6: 4. Go to each dataset sheet (Privacy / Luxury / Apparel) and enter the 15 pairwise ratings for each of the three criteria (Fidelity, Utility, Privacy) in the YELLOW input cells.
A7: 5. All weights, Consistency Ratios (CR), and the final composite AHP score update AUTOMATICALLY as you type — no manual calculation needed.
A8: 6. Check the 'Consistent?' flag after each block. If it shows '✗ FAIL', the judgements for that block are not logically consistent (CR ≥ 0.10) — ask the expert to review and revise those specific pairwise ratings.
A9: 7. The 'Final Scores' sheet aggregates everything into the final ranked AHP composite score per experiment, per dataset.
A10: 8. If multiple experts complete the survey, duplicate this workbook per expert, then average the final weight vectors across experts (geometric mean is preferred for AHP aggregation).

Sheet Criteria Weights
A1: Part A — Criteria Pairwise Comparison
A3: Criteria Comparison: Fidelity vs Utility vs Privacy
A4: Enter the expert's rating from the survey Part A. Positive = left item (Item A) preferred; negative = right item (Item B) preferred. Example: Fidelity vs Utility, rating +3 means 'Fidelity is moderately more important than Utility'.
A5: Item A | B5: Item B | C5: Rating (+1 to +9 = A wins; -1 to -9 = B wins)
A6: Fidelity | B6: Utility | C6: 1
A7: Fidelity | B7: Privacy | C7: 1
A8: Utility | B8: Privacy | C8: 1
A10: Pairwise Comparison Matrix (auto-calculated)
B11: Fidelity | C11: Utility | D11: Privacy
A12: Fidelity | B12: =1 -> 1 | C12: =IF(C6>=0,IF(C6=0,1,C6),1/ABS(C6)) -> 1 | D12: =IF(C7>=0,IF(C7=0,1,C7),1/ABS(C7)) -> 1
A13: Utility | B13: =1/C12 -> 1 | C13: =1 -> 1 | D13: =IF(C8>=0,IF(C8=0,1,C8),1/ABS(C8)) -> 1
A14: Privacy | B14: =1/D12 -> 1 | C14: =1/D13 -> 1 | D14: =1 -> 1
A16: Column Sum | B16: =SUM(B12:B14) -> 3 | C16: =SUM(C12:C14) -> 3 | D16: =SUM(D12:D14) -> 3
A18: Normalized Weights
A19: Item | B19: Priority Weight
A20: Fidelity | B20: =AVERAGE(B12/B16,C12/C16,D12/D16) -> 0.33333333
A21: Utility | B21: =AVERAGE(B13/B16,C13/C16,D13/D16) -> 0.33333333
A22: Privacy | B22: =AVERAGE(B14/B16,C14/C16,D14/D16) -> 0.33333333
A24: Consistency Check
A25: λ max | B25: =AVERAGE(((B12*B20+C12*B21+D12*B22)/B20),((B13*B20+C13*B21+D13*B22)/B21),((B14*B20+C14*B21+D14*B22)/B22)) -> 3
A26: CI = (λmax - n) / (n-1) | B26: =(B25-3)/2 -> 0
A27: RI (n=3) | B27: 0.58
A28: CR = CI / RI | B28: =IF(B27=0,0,B26/B27) -> 0
A29: Consistent? (CR < 0.10) | B29: =IF(B28<0.1,"✓ PASS","✗ FAIL — revise judgements") -> ✓ PASS

Sheet Privacy
A1: Part B — Privacy Dataset — Alternative Comparison
A3: Fidelity — Compare E1 through E6
A4: Enter the expert's 15 pairwise ratings for Fidelity from the survey (Part B, Privacy dataset, Fidelity section). Positive = left experiment preferred; negative = right experiment preferred.
A5: Item A | B5: Item B | C5: Rating (+1 to +9 = A wins; -1 to -9 = B wins)
A6: E1 | B6: E2 | C6: 1
A7: E1 | B7: E3 | C7: 1
A8: E1 | B8: E4 | C8: 1
A9: E1 | B9: E5 | C9: 1
A10: E1 | B10: E6 | C10: 1
A11: E2 | B11: E3 | C11: 1
A12: E2 | B12: E4 | C12: 1
A13: E2 | B13: E5 | C13: 1
A14: E2 | B14: E6 | C14: 1
A15: E3 | B15: E4 | C15: 1
A16: E3 | B16: E5 | C16: 1
A17: E3 | B17: E6 | C17: 1
... A20: E5 | B20: E6 | C20: 1
A22: Pairwise Comparison Matrix (auto-calculated)
B23: E1 | C23: E2 | D23: E3 | E23: E4 | F23: E5 | G23: E6
A24: E1 | B24: =1 -> 1 | C24: =IF(C6>=0,IF(C6=0,1,C6),1/ABS(C6)) -> 1 | D24: =IF(C7>=0,IF(C7=0,1,C7),1/ABS(C7)) -> 1 | E24: =IF(C8>=0,IF(C8=0,1,C8),1/ABS(C8)) -> 1 | F24: =IF(C9>=0,IF(C9=0,1,C9),1/ABS(C9)) -> 1 | G24: =IF(C10>=0,IF(C10=0,1,C10),1/ABS(C10)) -> 1
A25: E2 | B25: =1/C24 -> 1 | C25: =1 -> 1 | D25: =IF(C11>=0,IF(C11=0,1,C11),1/ABS(C11)) -> 1 | E25: =IF(C12>=0,IF(C12=0,1,C12),1/ABS(C12)) -> 1 | F25: =IF(C13>=0,IF(C13=0,1,C13),1/ABS(C13)) -> 1 | G25: =IF(C14>=0,IF(C14=0,1,C14),1/ABS(C14)) -> 1
A26: E3 | B26: =1/D24 -> 1 | C26: =1/D25 -> 1 | D26: =1 -> 1 | E26: =IF(C15>=0,IF(C15=0,1,C15),1/ABS(C15)) -> 1 | F26: =IF(C16>=0,IF(C16=0,1,C16),1/ABS(C16)) -> 1 | G26: =IF(C17>=0,IF(C17=0,1,C17),1/ABS(C17)) -> 1
A27: E4 | B27: =1/E24 -> 1 | C27: =1/E25 -> 1 | D27: =1/E26 -> 1 | E27: =1 -> 1 | F27: =IF(C18>=0,IF(C18=0,1,C18),1/ABS(C18)) -> 1 | G27: =IF(C19>=0,IF(C19=0,1,C19),1/ABS(C19)) -> 1
A28: E5 | B28: =1/F24 -> 1 | C28: =1/F25 -> 1 | D28: =1/F26 -> 1 | E28: =1/F27 -> 1 | F28: =1 -> 1 | G28: =IF(C20>=0,IF(C20=0,1,C20),1/ABS(C20)) -> 1
A29: E6 | B29: =1/G24 -> 1 | C29: =1/G25 -> 1 | D29: =1/G26 -> 1 | E29: =1/G27 -> 1 | F29: =1/G28 -> 1 | G29: =1 -> 1
A31: Column Sum | B31: =SUM(B24:B29) -> 6 | C31: =SUM(C24:C29) -> 6 | D31: =SUM(D24:D29) -> 6 | E31: =SUM(E24:E29) -> 6 | F31: =SUM(F24:F29) -> 6 | G31: =SUM(G24:G29) -> 6
A33: Normalized Weights
A34: Item | B34: Priority Weight
A35: E1 | B35: =AVERAGE(B24/B31,C24/C31,D24/D31,E24/E31,F24/F31,G24/G31) -> 0.16666667
A36: E2 | B36: =AVERAGE(B25/B31,C25/C31,D25/D31,E25/E31,F25/F31,G25/G31) -> 0.16666667
A37: E3 | B37: =AVERAGE(B26/B31,C26/C31,D26/D31,E26/E31,F26/F31,G26/G31) -> 0.16666667
A38: E4 | B38: =AVERAGE(B27/B31,C27/C31,D27/D31,E27/E31,F27/F31,G27/G31) -> 0.16666667
A39: E5 | B39: =AVERAGE(B28/B31,C28/C31,D28/D31,E28/E31,F28/F31,G28/G31) -> 0.16666667
A40: E6 | B40: =AVERAGE(B29/B31,C29/C31,D29/D31,E29/E31,F29/F31,G29/G31) -> 0.16666667
A42: Consistency Check
A43: λ max | B43: =AVERAGE(((B24*B35+C24*B36+D24*B37+E24*B38+F24*B39+G24*B40)/B35),((B25*B35+C25*B36+D25*B37+E25*B38+F25*B39+G25*B40)/B36),((B26*B35+C26*B36+D26*B37+E26*B38+F26*B39+G26*B40)/B37),((B27*B35+C27*B36+D27*B37+E27*B38+F27*B39+G27*B40)/B38),((B28*B35+C28*B36+D28*B37+E28*B38+F28*B39+G28*B40)/B39),((B29*B35+C29*B36+D29*B37+E29*B38+F29*B39+G29*B40)/B40)) -> 6
A44: CI = (λmax - n) / (n-1) | B44: =(B43-6)/5 -> 0
A45: RI (n=6) | B45: 1.24
A46: CR = CI / RI | B46: =IF(B45=0,0,B44/B45) -> 0
A47: Consistent? (CR < 0.10) | B47: =IF(B46<0.1,"✓ PASS","✗ FAIL — revise judgements") -> ✓ PASS
...

Sheet Luxury
A1: Part B — Luxury Dataset — Alternative Comparison
A3: Fidelity — Compare E1 through E6
A4: Enter the expert's 15 pairwise ratings for Fidelity from the survey (Part B, Luxury dataset, Fidelity section). Positive = left experiment preferred; negative = right experiment preferred.
A5: Item A | B5: Item B | C5: Rating (+1 to +9 = A wins; -1 to -9 = B wins)
A6: E1 | B6: E2 | C6: 1
A7: E1 | B7: E3 | C7: 1
A8: E1 | B8: E4 | C8: 1
A9: E1 | B9: E5 | C9: 1
A10: E1 | B10: E6 | C10: 1
A11: E2 | B11: E3 | C11: 1
A12: E2 | B12: E4 | C12: 1
A13: E2 | B13: E5 | C13: 1
A14: E2 | B14: E6 | C14: 1
A15: E3 | B15: E4 | C15: 1
A16: E3 | B16: E5 | C16: 1
A17: E3 | B17: E6 | C17: 1
... A20: E5 | B20: E6 | C20: 1
A22: Pairwise Comparison Matrix (auto-calculated)
B23: E1 | C23: E2 | D23: E3 | E23: E4 | F23: E5 | G23: E6
A24: E1 | B24: =1 -> 1 | C24: =IF(C6>=0,IF(C6=0,1,C6),1/ABS(C6)) -> 1 | D24: =IF(C7>=0,IF(C7=0,1,C7),1/ABS(C7)) -> 1 | E24: =IF(C8>=0,IF(C8=0,1,C8),1/ABS(C8)) -> 1 | F24: =IF(C9>=0,IF(C9=0,1,C9),1/ABS(C9)) -> 1 | G24: =IF(C10>=0,IF(C10=0,1,C10),1/ABS(C10)) -> 1
A25: E2 | B25: =1/C24 -> 1 | C25: =1 -> 1 | D25: =IF(C11>=0,IF(C11=0,1,C11),1/ABS(C11)) -> 1 | E25: =IF(C12>=0,IF(C12=0,1,C12),1/ABS(C12)) -> 1 | F25: =IF(C13>=0,IF(C13=0,1,C13),1/ABS(C13)) -> 1 | G25: =IF(C14>=0,IF(C14=0,1,C14),1/ABS(C14)) -> 1
A26: E3 | B26: =1/D24 -> 1 | C26: =1/D25 -> 1 | D26: =1 -> 1 | E26: =IF(C15>=0,IF(C15=0,1,C15),1/ABS(C15)) -> 1 | F26: =IF(C16>=0,IF(C16=0,1,C16),1/ABS(C16)) -> 1 | G26: =IF(C17>=0,IF(C17=0,1,C17),1/ABS(C17)) -> 1
A27: E4 | B27: =1/E24 -> 1 | C27: =1/E25 -> 1 | D27: =1/E26 -> 1 | E27: =1 -> 1 | F27: =IF(C18>=0,IF(C18=0,1,C18),1/ABS(C18)) -> 1 | G27: =IF(C19>=0,IF(C19=0,1,C19),1/ABS(C19)) -> 1
A28: E5 | B28: =1/F24 -> 1 | C28: =1/F25 -> 1 | D28: =1/F26 -> 1 | E28: =1/F27 -> 1 | F28: =1 -> 1 | G28: =IF(C20>=0,IF(C20=0,1,C20),1/ABS(C20)) -> 1
A29: E6 | B29: =1/G24 -> 1 | C29: =1/G25 -> 1 | D29: =1/G26 -> 1 | E29: =1/G27 -> 1 | F29: =1/G28 -> 1 | G29: =1 -> 1
A31: Column Sum | B31: =SUM(B24:B29) -> 6 | C31: =SUM(C24:C29) -> 6 | D31: =SUM(D24:D29) -> 6 | E31: =SUM(E24:E29) -> 6 | F31: =SUM(F24:F29) -> 6 | G31: =SUM(G24:G29) -> 6
A33: Normalized Weights
A34: Item | B34: Priority Weight
A35: E1 | B35: =AVERAGE(B24/B31,C24/C31,D24/D31,E24/E31,F24/F31,G24/G31) -> 0.16666667
A36: E2 | B36: =AVERAGE(B25/B31,C25/C31,D25/D31,E25/E31,F25/F31,G25/G31) -> 0.16666667
A37: E3 | B37: =AVERAGE(B26/B31,C26/C31,D26/D31,E26/E31,F26/F31,G26/G31) -> 0.16666667
A38: E4 | B38: =AVERAGE(B27/B31,C27/C31,D27/D31,E27/E31,F27/F31,G27/G31) -> 0.16666667
A39: E5 | B39: =AVERAGE(B28/B31,C28/C31,D28/D31,E28/E31,F28/F31,G28/G31) -> 0.16666667
A40: E6 | B40: =AVERAGE(B29/B31,C29/C31,D29/D31,E29/E31,F29/F31,G29/G31) -> 0.16666667
A42: Consistency Check
A43: λ max | B43: =AVERAGE(((B24*B35+C24*B36+D24*B37+E24*B38+F24*B39+G24*B40)/B35),((B25*B35+C25*B36+D25*B37+E25*B38+F25*B39+G25*B40)/B36),((B26*B35+C26*B36+D26*B37+E26*B38+F26*B39+G26*B40)/B37),((B27*B35+C27*B36+D27*B37+E27*B38+F27*B39+G27*B40)/B38),((B28*B35+C28*B36+D28*B37+E28*B38+F28*B39+G28*B40)/B39),((B29*B35+C29*B36+D29*B37+E29*B38+F29*B39+G29*B40)/B40)) -> 6
A44: CI = (λmax - n) / (n-1) | B44: =(B43-6)/5 -> 0
A45: RI (n=6) | B45: 1.24
A46: CR = CI / RI | B46: =IF(B45=0,0,B44/B45) -> 0
A47: Consistent? (CR < 0.10) | B47: =IF(B46<0.1,"✓ PASS","✗ FAIL — revise judgements") -> ✓ PASS
...

Sheet Apparel
A1: Part B — Apparel Dataset — Alternative Comparison
A3: Fidelity — Compare E1 through E6
A4: Enter the expert's 15 pairwise ratings for Fidelity from the survey (Part B, Apparel dataset, Fidelity section). Positive = left experiment preferred; negative = right experiment preferred.
A5: Item A | B5: Item B | C5: Rating (+1 to +9 = A wins; -1 to -9 = B wins)
A6: E1 | B6: E2 | C6: 1
A7: E1 | B7: E3 | C7: 1
A8: E1 | B8: E4 | C8: 1
A9: E1 | B9: E5 | C9: 1
A10: E1 | B10: E6 | C10: 1
A11: E2 | B11: E3 | C11: 1
A12: E2 | B12: E4 | C12: 1
A13: E2 | B13: E5 | C13: 1
A14: E2 | B14: E6 | C14: 1
A15: E3 | B15: E4 | C15: 1
A16: E3 | B16: E5 | C16: 1
A17: E3 | B17: E6 | C17: 1
... A20: E5 | B20: E6 | C20: 1
A22: Pairwise Comparison Matrix (auto-calculated)
B23: E1 | C23: E2 | D23: E3 | E23: E4 | F23: E5 | G23: E6
A24: E1 | B24: =1 -> 1 | C24: =IF(C6>=0,IF(C6=0,1,C6),1/ABS(C6)) -> 1 | D24: =IF(C7>=0,IF(C7=0,1,C7),1/ABS(C7)) -> 1 | E24: =IF(C8>=0,IF(C8=0,1,C8),1/ABS(C8)) -> 1 | F24: =IF(C9>=0,IF(C9=0,1,C9),1/ABS(C9)) -> 1 | G24: =IF(C10>=0,IF(C10=0,1,C10),1/ABS(C10)) -> 1
A25: E2 | B25: =1/C24 -> 1 | C25: =1 -> 1 | D25: =IF(C11>=0,IF(C11=0,1,C11),1/ABS(C11)) -> 1 | E25: =IF(C12>=0,IF(C12=0,1,C12),1/ABS(C12)) -> 1 | F25: =IF(C13>=0,IF(C13=0,1,C13),1/ABS(C13)) -> 1 | G25: =IF(C14>=0,IF(C14=0,1,C14),1/ABS(C14)) -> 1
A26: E3 | B26: =1/D24 -> 1 | C26: =1/D25 -> 1 | D26: =1 -> 1 | E26: =IF(C15>=0,IF(C15=0,1,C15),1/ABS(C15)) -> 1 | F26: =IF(C16>=0,IF(C16=0,1,C16),1/ABS(C16)) -> 1 | G26: =IF(C17>=0,IF(C17=0,1,C17),1/ABS(C17)) -> 1
A27: E4 | B27: =1/E24 -> 1 | C27: =1/E25 -> 1 | D27: =1/E26 -> 1 | E27: =1 -> 1 | F27: =IF(C18>=0,IF(C18=0,1,C18),1/ABS(C18)) -> 1 | G27: =IF(C19>=0,IF(C19=0,1,C19),1/ABS(C19)) -> 1
A28: E5 | B28: =1/F24 -> 1 | C28: =1/F25 -> 1 | D28: =1/F26 -> 1 | E28: =1/F27 -> 1 | F28: =1 -> 1 | G28: =IF(C20>=0,IF(C20=0,1,C20),1/ABS(C20)) -> 1
A29: E6 | B29: =1/G24 -> 1 | C29: =1/G25 -> 1 | D29: =1/G26 -> 1 | E29: =1/G27 -> 1 | F29: =1/G28 -> 1 | G29: =1 -> 1
A31: Column Sum | B31: =SUM(B24:B29) -> 6 | C31: =SUM(C24:C29) -> 6 | D31: =SUM(D24:D29) -> 6 | E31: =SUM(E24:E29) -> 6 | F31: =SUM(F24:F29) -> 6 | G31: =SUM(G24:G29) -> 6
A33: Normalized Weights
A34: Item | B34: Priority Weight
A35: E1 | B35: =AVERAGE(B24/B31,C24/C31,D24/D31,E24/E31,F24/F31,G24/G31) -> 0.16666667
A36: E2 | B36: =AVERAGE(B25/B31,C25/C31,D25/D31,E25/E31,F25/F31,G25/G31) -> 0.16666667
A37: E3 | B37: =AVERAGE(B26/B31,C26/C31,D26/D31,E26/E31,F26/F31,G26/G31) -> 0.16666667
A38: E4 | B38: =AVERAGE(B27/B31,C27/C31,D27/D31,E27/E31,F27/F31,G27/G31) -> 0.16666667
A39: E5 | B39: =AVERAGE(B28/B31,C28/C31,D28/D31,E28/E31,F28/F31,G28/G31) -> 0.16666667
A40: E6 | B40: =AVERAGE(B29/B31,C29/C31,D29/D31,E29/E31,F29/F31,G29/G31) -> 0.16666667
A42: Consistency Check
A43: λ max | B43: =AVERAGE(((B24*B35+C24*B36+D24*B37+E24*B38+F24*B39+G24*B40)/B35),((B25*B35+C25*B36+D25*B37+E25*B38+F25*B39+G25*B40)/B36),((B26*B35+C26*B36+D26*B37+E26*B38+F26*B39+G26*B40)/B37),((B27*B35+C27*B36+D27*B37+E27*B38+F27*B39+G27*B40)/B38),((B28*B35+C28*B36+D28*B37+E28*B38+F28*B39+G28*B40)/B39),((B29*B35+C29*B36+D29*B37+E29*B38+F29*B39+G29*B40)/B40)) -> 6
A44: CI = (λmax - n) / (n-1) | B44: =(B43-6)/5 -> 0
A45: RI (n=6) | B45: 1.24
A46: CR = CI / RI | B46: =IF(B45=0,0,B44/B45) -> 0
A47: Consistent? (CR < 0.10) | B47: =IF(B46<0.1,"✓ PASS","✗ FAIL — revise judgements") -> ✓ PASS
...

Sheet Final Scores
A1: Final AHP Composite Scores (auto-calculated)
A3: Composite Score = w(Fidelity)×Fid_weight(Exp) + w(Utility)×Util_weight(Exp) + w(Privacy)×Priv_weight(Exp)
A5: Dataset: Privacy
A6: Rank | B6: Experiment | C6: Method | D6: Fidelity weight | E6: Utility weight | F6: Privacy weight | G6: Composite Score
A7: =RANK(G7,$G$7:$G$12) -> 1 | B7: E1 | C7: LLM Baseline | D7: =Privacy!B35 -> 0.16666667 | E7: =Privacy!B82 -> 0.16666667 | F7: =Privacy!B129 -> 0.16666667 | G7: ='Criteria Weights'!B20*D7+'Criteria Weights'!B21*E7+'Criteria Weights'!B22*F7 -> 0.16666667
A8: =RANK(G8,$G$7:$G$12) -> 1 | B8: E2 | C8: CTGAN Global | D8: =Privacy!B36 -> 0.16666667 | E8: =Privacy!B83 -> 0.16666667 | F8: =Privacy!B130 -> 0.16666667 | G8: ='Criteria Weights'!B20*D8+'Criteria Weights'!B21*E8+'Criteria Weights'!B22*F8 -> 0.16666667
A9: =RANK(G9,$G$7:$G$12) -> 1 | B9: E3 | C9: Copula Global | D9: =Privacy!B37 -> 0.16666667 | E9: =Privacy!B84 -> 0.16666667 | F9: =Privacy!B131 -> 0.16666667 | G9: ='Criteria Weights'!B20*D9+'Criteria Weights'!B21*E9+'Criteria Weights'!B22*F9 -> 0.16666667
A10: =RANK(G10,$G$7:$G$12) -> 1 | B10: E4 | C10: LLM + Segmentation | D10: =Privacy!B38 -> 0.16666667 | E10: =Privacy!B85 -> 0.16666667 | F10: =Privacy!B132 -> 0.16666667 | G10: ='Criteria Weights'!B20*D10+'Criteria Weights'!B21*E10+'Criteria Weights'!B22*F10 -> 0.16666667
A11: =RANK(G11,$G$7:$G$12) -> 1 | B11: E5 | C11: Copula + Segmentation | D11: =Privacy!B39 -> 0.16666667 | E11: =Privacy!B86 -> 0.16666667 | F11: =Privacy!B133 -> 0.16666667 | G11: ='Criteria Weights'!B20*D11+'Criteria Weights'!B21*E11+'Criteria Weights'!B22*F11 -> 0.16666667
A12: =RANK(G12,$G$7:$G$12) -> 1 | B12: E6 | C12: CTGAN + Segmentation | D12: =Privacy!B40 -> 0.16666667 | E12: =Privacy!B87 -> 0.16666667 | F12: =Privacy!B134 -> 0.16666667 | G12: ='Criteria Weights'!B20*D12+'Criteria Weights'!B21*E12+'Criteria Weights'!B22*F12 -> 0.16666667
A15: Dataset: Luxury
A16: Rank | B16: Experiment | C16: Method | D16: Fidelity weight | E16: Utility weight | F16: Privacy weight | G16: Composite Score
A17: =RANK(G17,$G$17:$G$22) -> 1 | B17: E1 | C17: LLM Baseline | D17: =Luxury!B35 -> 0.16666667 | E17: =Luxury!B82 -> 0.16666667 | F17: =Luxury!B129 -> 0.16666667 | G17: ='Criteria Weights'!B20*D17+'Criteria Weights'!B21*E17+'Criteria Weights'!B22*F17 -> 0.16666667
A18: =RANK(G18,$G$17:$G$22) -> 1 | B18: E2 | C18: CTGAN Global | D18: =Luxury!B36 -> 0.16666667 | E18: =Luxury!B83 -> 0.16666667 | F18: =Luxury!B130 -> 0.16666667 | G18: ='Criteria Weights'!B20*D18+'Criteria Weights'!B21*E18+'Criteria Weights'!B22*F18 -> 0.16666667
A19: =RANK(G19,$G$17:$G$22) -> 1 | B19: E3 | C19: Copula Global | D19: =Luxury!B37 -> 0.16666667 | E19: =Luxury!B84 -> 0.16666667 | F19: =Luxury!B131 -> 0.16666667 | G19: ='Criteria Weights'!B20*D19+'Criteria Weights'!B21*E19+'Criteria Weights'!B22*F19 -> 0.16666667
A20: =RANK(G20,$G$17:$G$22) -> 1 | B20: E4 | C20: LLM + Segmentation | D20: =Luxury!B38 -> 0.16666667 | E20: =Luxury!B85 -> 0.16666667 | F20: =Luxury!B132 -> 0.16666667 | G20: ='Criteria Weights'!B20*D20+'Criteria Weights'!B21*E20+'Criteria Weights'!B22*F20 -> 0.16666667
A21: =RANK(G21,$G$17:$G$22) -> 1 | B21: E5 | C21: Copula + Segmentation | D21: =Luxury!B39 -> 0.16666667 | E21: =Luxury!B86 -> 0.16666667 | F21: =Luxury!B133 -> 0.16666667 | G21: ='Criteria Weights'!B20*D21+'Criteria Weights'!B21*E21+'Criteria Weights'!B22*F21 -> 0.16666667
A22: =RANK(G22,$G$17:$G$22) -> 1 | B22: E6 | C22: CTGAN + Segmentation | D22: =Luxury!B40 -> 0.16666667 | E22: =Luxury!B87 -> 0.16666667 | F22: =Luxury!B134 -> 0.16666667 | G22: ='Criteria Weights'!B20*D22+'Criteria Weights'!B21*E22+'Criteria Weights'!B22*F22 -> 0.16666667
A25: Dataset: Apparel
A26: Rank | B26: Experiment | C26: Method | D26: Fidelity weight | E26: Utility weight | F26: Privacy weight | G26: Composite Score
A27: =RANK(G27,$G$27:$G$32) -> 1 | B27: E1 | C27: LLM Baseline | D27: =Apparel!B35 -> 0.16666667 | E27: =Apparel!B82 -> 0.16666667 | F27: =Apparel!B129 -> 0.16666667 | G27: ='Criteria Weights'!B20*D27+'Criteria Weights'!B21*E27+'Criteria Weights'!B22*F27 -> 0.16666667
A28: =RANK(G28,$G$27:$G$32) -> 1 | B28: E2 | C28: CTGAN Global | D28: =Apparel!B36 -> 0.16666667 | E28: =Apparel!B83 -> 0.16666667 | F28: =Apparel!B130 -> 0.16666667 | G28: ='Criteria Weights'!B20*D28+'Criteria Weights'!B21*E28+'Criteria Weights'!B22*F28 -> 0.16666667
A29: =RANK(G29,$G$27:$G$32) -> 1 | B29: E3 | C29: Copula Global | D29: =Apparel!B37 -> 0.16666667 | E29: =Apparel!B84 -> 0.16666667 | F29: =Apparel!B131 -> 0.16666667 | G29: ='Criteria Weights'!B20*D29+'Criteria Weights'!B21*E29+'Criteria Weights'!B22*F29 -> 0.16666667
A30: =RANK(G30,$G$27:$G$32) -> 1 | B30: E4 | C30: LLM + Segmentation | D30: =Apparel!B38 -> 0.16666667 | E30: =Apparel!B85 -> 0.16666667 | F30: =Apparel!B132 -> 0.16666667 | G30: ='Criteria Weights'!B20*D30+'Criteria Weights'!B21*E30+'Criteria Weights'!B22*F30 -> 0.16666667
A31: =RANK(G31,$G$27:$G$32) -> 1 | B31: E5 | C31: Copula + Segmentation | D31: =Apparel!B39 -> 0.16666667 | E31: =Apparel!B86 -> 0.16666667 | F31: =Apparel!B133 -> 0.16666667 | G31: ='Criteria Weights'!B20*D31+'Criteria Weights'!B21*E31+'Criteria Weights'!B22*F31 -> 0.16666667
A32: =RANK(G32,$G$27:$G$32) -> 1 | B32: E6 | C32: CTGAN + Segmentation | D32: =Apparel!B40 -> 0.16666667 | E32: =Apparel!B87 -> 0.16666667 | F32: =Apparel!B134 -> 0.16666667 | G32: ='Criteria Weights'!B20*D32+'Criteria Weights'!B21*E32+'Criteria Weights'!B22*F32 -> 0.16666667
